<?xml version="1.0"?>
<robot name="pendulum">
  <link name="base_link">
    <visual>
      <geometry>
        <box size="0.1 0.5 0.5"/>
      </geometry>
      <origin rpy="0 0 0" xyz="0 0 0"/>
    </visual>
  </link>

  <link name="pendulum_link">
    <visual>
      <geometry>
        <cylinder length="1.0" radius="0.1"/>
      </geometry>
      <origin rpy="0 0 0" xyz="0 0 0.5"/>
    </visual>
    <inertial>
      <mass value="10"/>
      <inertia ixx="0.4" ixy="0.0" ixz="0.0" iyy="0.4" iyz="0.0" izz="0.2"/>
    </inertial>
  </link>

  <joint name="base_to_pendulum" type="revolute">
    <axis xyz="1 0 0"/>
    <limit effort="1000.0" velocity="0.5"/>
    <parent link="base_link"/>
    <child link="pendulum_link"/>
    <origin xyz="0.1 0.0 0.0"/>
  </joint>

</robot>